<mujoco model="wam(v1.31)">
  <option integrator="Euler" timestep="0.002"/>
  <compiler coordinate="local" angle="radian" meshdir="[ASSETS_DIR]/meshes/barrett_wam"/>

  <default>
    <joint type="hinge" limited="true" pos="0 0 0" axis="0 0 1" frictionloss=".001"/>
    <default class="viz">
      <geom type="mesh" contype="0" conaffinity="0" group="1" rgba="0.7 0.7 0.7 1"/>
    </default>
    <default class="col">
      <geom type="mesh" contype="0" conaffinity="1" group="0" rgba="0.5 0.6 0.7 1"/>
    </default>
  </default>

  <asset>
    <mesh file="base_link_fine.stl"/>
    <mesh file="base_link_convex.stl"/>
    <mesh file="shoulder_link_fine.stl"/>
    <mesh file="shoulder_link_convex_decomposition_p1.stl"/>
    <mesh file="shoulder_link_convex_decomposition_p2.stl"/>
    <mesh file="shoulder_link_convex_decomposition_p3.stl"/>
    <mesh file="shoulder_pitch_link_fine.stl"/>
    <mesh file="shoulder_pitch_link_convex.stl"/>
    <mesh file="upper_arm_link_fine.stl"/>
    <mesh file="upper_arm_link_convex_decomposition_p1.stl"/>
    <mesh file="upper_arm_link_convex_decomposition_p2.stl"/>
    <mesh file="elbow_link_fine.stl"/>
    <mesh file="elbow_link_convex.stl"/>
    <mesh file="forearm_link_fine.stl"/>
    <mesh file="forearm_link_convex_decomposition_p1.stl"/>
    <mesh file="forearm_link_convex_decomposition_p2.stl"/>
    <mesh file="wrist_yaw_link_fine.stl"/>
    <mesh file="wrist_yaw_link_convex_decomposition_p1.stl"/>
    <mesh file="wrist_yaw_link_convex_decomposition_p2.stl"/>
    <mesh file="wrist_pitch_link_fine.stl"/>
    <mesh file="wrist_pitch_link_convex_decomposition_p1.stl"/>
    <mesh file="wrist_pitch_link_convex_decomposition_p2.stl"/>
    <mesh file="wrist_pitch_link_convex_decomposition_p3.stl"/>
    <mesh file="wrist_palm_link_fine.stl"/>
    <mesh file="wrist_palm_link_convex.stl"/>
    <texture name="groundplane" type="2d" builtin="checker" rgb1=".25 .26 .25"
             rgb2=".22 .22 .22" width="100" height="100" mark="edge" markrgb=".3 .3 .3"/>
    <material name="MatGnd" texture="groundplane" texrepeat="5 5" specular="1" shininess=".3"
              reflectance="0.00001"/>
  </asset>

  <worldbody>
    <light directional="true" cutoff="60" exponent="1" diffuse="1 1 1" specular=".1 .1 .1" pos=".1 .2 1.3" dir="-.1 -.2 -1.3"/>
    <geom name="ground" type="plane" pos="0 0 0" size="1.5 2 1" conaffinity="1" contype="1" material="MatGnd"/>

    <body name="wam/base_link" pos="0 0 .6">
      <geom class="viz" mesh="base_link_fine" quat="0.707107 0 0 -0.707107"/>
      <geom class="col" mesh="base_link_convex" quat="0.707107 0 0 -0.707107"/>
      <body name="wam/shoulder_yaw_link" pos="0 0 0.160" quat="0.707107 0 0 -0.707107">
        <inertial pos="-0.00443422 -0.00066489 -0.12189039" mass="10.76768767"
                  fullinertia="0.50739925 0.46298222 0.11328369 0.00012485 -0.00213041 0.00068555"/>
        <joint name="wam/base_yaw_joint" range="-2.6 2.6"/>
        <geom class="viz" mesh="shoulder_link_fine" pos="0 0 0.186"/>
        <geom class="col" mesh="shoulder_link_convex_decomposition_p1" pos="0 0 0.186"/>
        <geom class="col" mesh="shoulder_link_convex_decomposition_p2" pos="0 0 0.186"/>
        <geom class="col" mesh="shoulder_link_convex_decomposition_p3" pos="0 0 0.186"/>
        <body name="wam/shoulder_pitch_link" pos="0 0 0.184" quat="0.707107 -0.707107 0 0">
          <inertial pos="-0.00236983 -0.01542114 0.03105614" mass="3.87493756"
                    fullinertia="0.02140958 0.01558906 0.01377875 0.00002461 -0.00027172 -0.00181920"/>
          <joint name="wam/shoulder_pitch_joint" range="-1.985 1.985"/>
          <geom class="viz" mesh="shoulder_pitch_link_fine"/>
          <geom class="col" mesh="shoulder_pitch_link_convex"/>
          <body name="wam/upper_arm_link" pos="0 -0.505 0" quat="0.707107 0.707107 0 0">
            <inertial pos="-0.03825858 0.00003309 -0.20750770" mass="1.80228141"
                      fullinertia="0.06276039 0.06656967 0.00689512 -0.00000738 -0.00614574 -0.00001767"/>
            <joint name="wam/shoulder_yaw_joint" range="-2.8 2.8"/>
            <geom class="viz" mesh="upper_arm_link_fine" pos="0 0 -0.505"/>
            <geom class="col" mesh="upper_arm_link_convex_decomposition_p1" pos="0 0 -0.505"/>
            <geom class="col" mesh="upper_arm_link_convex_decomposition_p2" pos="0 0 -0.505"/>
            <body name="wam/forearm_link" pos="0.045 0 0.045" quat="0.707107 -0.707107 0 0">
              <inertial pos="0.00498512 -0.13271662 -0.00022942" mass="2.40016804"
                        fullinertia="0.01491672 0.00780497 0.01968956 -0.00150604 -0.00001741 -0.00002109"/>
              <joint name="wam/elbow_pitch_joint" range="-0.9 3.14159"/>
              <geom class="viz" mesh="elbow_link_fine"/>
              <geom class="col" mesh="elbow_link_convex"/>
              <geom class="viz" mesh="forearm_link_fine" pos="-.045 -0.0730 0" euler="1.57 0 0"/>
              <geom class="col" mesh="forearm_link_convex_decomposition_p1" pos="-0.045 -0.0730 0" euler="1.57 0 0"/>
              <geom class="col" mesh="forearm_link_convex_decomposition_p2" pos="-.045 -0.0730 0" euler="1.57 0 0"/>
              <body name="wam/wrist_yaw_link" pos="-0.045 0 0" quat="0.707107 0.707107 0 0">
                <inertial pos="0.00008921 0.00435824 -0.00511217" mass="0.12376019"
                          fullinertia="0.01118871 0.01120112 0.00007582 0.00000005 0.00000020 -0.00000359"/>
                <joint name="wam/wrist_yaw_joint" range="-4.55 1.25"/>
                <geom class="viz" mesh="wrist_yaw_link_fine" pos="0 0 0.3"/>
                <geom class="col" mesh="wrist_yaw_link_convex_decomposition_p1" pos="0 0 0.3"/>
                <geom class="col" mesh="wrist_yaw_link_convex_decomposition_p2" pos="0 0 0.3"/>
                <body name="wam/wrist_pitch_link" pos="0 0 0.3" quat="0.707107 -0.707107 0 0">
                  <inertial pos="-0.00012262 -0.02468336 -0.01703194" mass="0.41797364"
                            fullinertia="0.00055516 0.00045358 0.00024367 -0.00000074 -0.00000061 -0.00004590"/>
                  <joint name="wam/wrist_pitch_joint" range="-1.5707 1.5707"/>
                  <geom class="viz" mesh="wrist_pitch_link_fine" pos="0 0 0"/>
                  <geom class="col" mesh="wrist_pitch_link_convex_decomposition_p1"/>
                  <geom class="col" mesh="wrist_pitch_link_convex_decomposition_p2"/>
                  <geom class="col" mesh="wrist_pitch_link_convex_decomposition_p3"/>
                  <body name="wam/wrist_palm_link" pos="0 -0.06 0" quat="0.707107 0.707107 0 0">
                    <inertial pos="-0.00007974 -0.00323552 -0.00016313" mass="0.06864753"
                              fullinertia="0.00003773 0.00007408 0.00003806 0.00000000 -0.00000019 0.00000000"/>
                    <joint name="wam/palm_yaw_joint" range="-2.7 2.7"/>
                    <geom class="viz" mesh="wrist_palm_link_fine" pos="0 0 -0.06"/>
                    <geom class="col" mesh="wrist_palm_link_convex" pos="0 0 -0.06"/>
                    <!-- Include your endeffector here via: -->
                    <!--<include file="file_name.xml"/>-->

                    <!-- Note that the XML Tags in this XML file should be enclosed by the following
                    parent XML Tag
                    <mujocoinclude>
                    ...
                    </mujocoinclude>-->
                  </body>
                </body>
              </body>
            </body>
          </body>
        </body>
      </body>
    </body>
  </worldbody>
</mujoco>
